Performing system checks...

System check identified no issues (0 silenced).
November 17, 2017 - 11:37:01
Django version 1.11.7, using settings 'anm.settings'
Starting development server at http://0:8000/
Quit the server with CONTROL-C.
Unhandled exception in thread started by <function check_errors.<locals>.wrapper at 0x7fe157832ea0>
Traceback (most recent call last):
  File "/usr/local/lib/python3.5/dist-packages/django/utils/autoreload.py", line 228, in wrapper
    fn(*args, **kwargs)
  File "/usr/local/lib/python3.5/dist-packages/django/core/management/commands/runserver.py", line 125, in inner_run
    self.check(display_num_errors=True)
  File "/usr/local/lib/python3.5/dist-packages/django/core/management/base.py", line 359, in check
    include_deployment_checks=include_deployment_checks,
  File "/usr/local/lib/python3.5/dist-packages/django/core/management/base.py", line 346, in _run_checks
    return checks.run_checks(**kwargs)
  File "/usr/local/lib/python3.5/dist-packages/django/core/checks/registry.py", line 81, in run_checks
    new_errors = check(app_configs=app_configs)
  File "/usr/local/lib/python3.5/dist-packages/django/core/checks/urls.py", line 16, in check_url_config
    return check_resolver(resolver)
  File "/usr/local/lib/python3.5/dist-packages/django/core/checks/urls.py", line 26, in check_resolver
    return check_method()
  File "/usr/local/lib/python3.5/dist-packages/django/urls/resolvers.py", line 254, in check
    for pattern in self.url_patterns:
  File "/usr/local/lib/python3.5/dist-packages/django/utils/functional.py", line 35, in __get__
    res = instance.__dict__[self.name] = self.func(instance)
  File "/usr/local/lib/python3.5/dist-packages/django/urls/resolvers.py", line 405, in url_patterns
    patterns = getattr(self.urlconf_module, "urlpatterns", self.urlconf_module)
  File "/usr/local/lib/python3.5/dist-packages/django/utils/functional.py", line 35, in __get__
    res = instance.__dict__[self.name] = self.func(instance)
  File "/usr/local/lib/python3.5/dist-packages/django/urls/resolvers.py", line 398, in urlconf_module
    return import_module(self.urlconf_name)
  File "/usr/lib/python3.5/importlib/__init__.py", line 126, in import_module
    return _bootstrap._gcd_import(name[level:], package, level)
  File "<frozen importlib._bootstrap>", line 986, in _gcd_import
  File "<frozen importlib._bootstrap>", line 969, in _find_and_load
  File "<frozen importlib._bootstrap>", line 958, in _find_and_load_unlocked
  File "<frozen importlib._bootstrap>", line 673, in _load_unlocked
  File "<frozen importlib._bootstrap_external>", line 661, in exec_module
  File "<frozen importlib._bootstrap_external>", line 767, in get_code
  File "<frozen importlib._bootstrap_external>", line 727, in source_to_code
  File "<frozen importlib._bootstrap>", line 222, in _call_with_frames_removed
  File "/home/ubuntu/anmgr1/Device-Inventory-Alpha/anm/anm/urls.py", line 22
    url(r'^api/', include('api.urls'))
      ^
SyntaxError: invalid syntax
Performing system checks...

